Traceback (most recent call last):
  File "/opt/hostedtoolcache/Python/3.10.11/x64/lib/python3.10/site-packages/jupyter_cache/executors/utils.py", line 51, in single_nb_execution
    executenb(
  File "/opt/hostedtoolcache/Python/3.10.11/x64/lib/python3.10/site-packages/nbclient/client.py", line 1204, in execute
    return NotebookClient(nb=nb, resources=resources, km=km, **kwargs).execute()
  File "/opt/hostedtoolcache/Python/3.10.11/x64/lib/python3.10/site-packages/nbclient/util.py", line 84, in wrapped
    return just_run(coro(*args, **kwargs))
  File "/opt/hostedtoolcache/Python/3.10.11/x64/lib/python3.10/site-packages/nbclient/util.py", line 62, in just_run
    return loop.run_until_complete(coro)
  File "/opt/hostedtoolcache/Python/3.10.11/x64/lib/python3.10/asyncio/base_events.py", line 649, in run_until_complete
    return future.result()
  File "/opt/hostedtoolcache/Python/3.10.11/x64/lib/python3.10/site-packages/nbclient/client.py", line 663, in async_execute
    await self.async_execute_cell(
  File "/opt/hostedtoolcache/Python/3.10.11/x64/lib/python3.10/site-packages/nbclient/client.py", line 965, in async_execute_cell
    await self._check_raise_for_error(cell, cell_index, exec_reply)
  File "/opt/hostedtoolcache/Python/3.10.11/x64/lib/python3.10/site-packages/nbclient/client.py", line 862, in _check_raise_for_error
    raise CellExecutionError.from_cell_and_msg(cell, exec_reply_content)
nbclient.exceptions.CellExecutionError: An error occurred while executing the following cell:
------------------
pd.set_option("display.max_rows", int(1e3))
score_differences = get_score_comparisons(
    plutocracy_report_data, plutocracy_report_data_filtered
)

------------------

[0;31m---------------------------------------------------------------------------[0m
[0;31mKeyError[0m                                  Traceback (most recent call last)
File [0;32m/opt/hostedtoolcache/Python/3.10.11/x64/lib/python3.10/site-packages/pandas/core/indexes/base.py:3803[0m, in [0;36mIndex.get_loc[0;34m(self, key, method, tolerance)[0m
[1;32m   3802[0m [38;5;28;01mtry[39;00m:
[0;32m-> 3803[0m     [38;5;28;01mreturn[39;00m [38;5;28;43mself[39;49m[38;5;241;43m.[39;49m[43m_engine[49m[38;5;241;43m.[39;49m[43mget_loc[49m[43m([49m[43mcasted_key[49m[43m)[49m
[1;32m   3804[0m [38;5;28;01mexcept[39;00m [38;5;167;01mKeyError[39;00m [38;5;28;01mas[39;00m err:

File [0;32m/opt/hostedtoolcache/Python/3.10.11/x64/lib/python3.10/site-packages/pandas/_libs/index.pyx:138[0m, in [0;36mpandas._libs.index.IndexEngine.get_loc[0;34m()[0m

File [0;32m/opt/hostedtoolcache/Python/3.10.11/x64/lib/python3.10/site-packages/pandas/_libs/index.pyx:165[0m, in [0;36mpandas._libs.index.IndexEngine.get_loc[0;34m()[0m

File [0;32mpandas/_libs/hashtable_class_helper.pxi:5745[0m, in [0;36mpandas._libs.hashtable.PyObjectHashTable.get_item[0;34m()[0m

File [0;32mpandas/_libs/hashtable_class_helper.pxi:5753[0m, in [0;36mpandas._libs.hashtable.PyObjectHashTable.get_item[0;34m()[0m

[0;31mKeyError[0m: 'proposal_title'

The above exception was the direct cause of the following exception:

[0;31mKeyError[0m                                  Traceback (most recent call last)
Cell [0;32mIn[4], line 2[0m
[1;32m      1[0m pd[38;5;241m.[39mset_option([38;5;124m"[39m[38;5;124mdisplay.max_rows[39m[38;5;124m"[39m, [38;5;28mint[39m([38;5;241m1e3[39m))
[0;32m----> 2[0m score_differences [38;5;241m=[39m [43mget_score_comparisons[49m[43m([49m
[1;32m      3[0m [43m    [49m[43mplutocracy_report_data[49m[43m,[49m[43m [49m[43mplutocracy_report_data_filtered[49m
[1;32m      4[0m [43m)[49m

File [0;32m~/work/gov_analysis/gov_analysis/stages/data_processing/statistics.py:119[0m, in [0;36mget_score_comparisons[0;34m(dao_proposals, dao_proposals_filtered)[0m
[1;32m    115[0m         [38;5;28;01melse[39;00m:
[1;32m    116[0m             whale_voting_power [38;5;241m=[39m [38;5;28msum[39m(score_differences)
[1;32m    118[0m         organization_proposals[first_row[[38;5;124m"[39m[38;5;124mproposal_id[39m[38;5;124m"[39m]] [38;5;241m=[39m [
[0;32m--> 119[0m             [43mfirst_row[49m[43m[[49m[38;5;124;43m"[39;49m[38;5;124;43mproposal_title[39;49m[38;5;124;43m"[39;49m[43m][49m,
[1;32m    120[0m             first_row[[38;5;124m"[39m[38;5;124mproposal_start[39m[38;5;124m"[39m],
[1;32m    121[0m             first_row[[38;5;124m"[39m[38;5;124mproposal_end[39m[38;5;124m"[39m],
[1;32m    122[0m             score_differences,
[1;32m    123[0m             whale_voting_power [38;5;241m/[39m total_voting_power,
[1;32m    124[0m             total_voting_power,
[1;32m    125[0m             [38;5;129;01mnot[39;00m unfiltered_winning_choice_index
[1;32m    126[0m             [38;5;241m==[39m filtered_winning_choice_index,
[1;32m    127[0m             choices[unfiltered_winning_choice_index],
[1;32m    128[0m             choices[filtered_winning_choice_index],
[1;32m    129[0m         ]
[1;32m    130[0m [38;5;28;01mreturn[39;00m differences

File [0;32m/opt/hostedtoolcache/Python/3.10.11/x64/lib/python3.10/site-packages/pandas/core/series.py:981[0m, in [0;36mSeries.__getitem__[0;34m(self, key)[0m
[1;32m    978[0m     [38;5;28;01mreturn[39;00m [38;5;28mself[39m[38;5;241m.[39m_values[key]
[1;32m    980[0m [38;5;28;01melif[39;00m key_is_scalar:
[0;32m--> 981[0m     [38;5;28;01mreturn[39;00m [38;5;28;43mself[39;49m[38;5;241;43m.[39;49m[43m_get_value[49m[43m([49m[43mkey[49m[43m)[49m
[1;32m    983[0m [38;5;28;01mif[39;00m is_hashable(key):
[1;32m    984[0m     [38;5;66;03m# Otherwise index.get_value will raise InvalidIndexError[39;00m
[1;32m    985[0m     [38;5;28;01mtry[39;00m:
[1;32m    986[0m         [38;5;66;03m# For labels that don't resolve as scalars like tuples and frozensets[39;00m

File [0;32m/opt/hostedtoolcache/Python/3.10.11/x64/lib/python3.10/site-packages/pandas/core/series.py:1089[0m, in [0;36mSeries._get_value[0;34m(self, label, takeable)[0m
[1;32m   1086[0m     [38;5;28;01mreturn[39;00m [38;5;28mself[39m[38;5;241m.[39m_values[label]
[1;32m   1088[0m [38;5;66;03m# Similar to Index.get_value, but we do not fall back to positional[39;00m
[0;32m-> 1089[0m loc [38;5;241m=[39m [38;5;28;43mself[39;49m[38;5;241;43m.[39;49m[43mindex[49m[38;5;241;43m.[39;49m[43mget_loc[49m[43m([49m[43mlabel[49m[43m)[49m
[1;32m   1090[0m [38;5;28;01mreturn[39;00m [38;5;28mself[39m[38;5;241m.[39mindex[38;5;241m.[39m_get_values_for_loc([38;5;28mself[39m, loc, label)

File [0;32m/opt/hostedtoolcache/Python/3.10.11/x64/lib/python3.10/site-packages/pandas/core/indexes/base.py:3805[0m, in [0;36mIndex.get_loc[0;34m(self, key, method, tolerance)[0m
[1;32m   3803[0m     [38;5;28;01mreturn[39;00m [38;5;28mself[39m[38;5;241m.[39m_engine[38;5;241m.[39mget_loc(casted_key)
[1;32m   3804[0m [38;5;28;01mexcept[39;00m [38;5;167;01mKeyError[39;00m [38;5;28;01mas[39;00m err:
[0;32m-> 3805[0m     [38;5;28;01mraise[39;00m [38;5;167;01mKeyError[39;00m(key) [38;5;28;01mfrom[39;00m [38;5;21;01merr[39;00m
[1;32m   3806[0m [38;5;28;01mexcept[39;00m [38;5;167;01mTypeError[39;00m:
[1;32m   3807[0m     [38;5;66;03m# If we have a listlike key, _check_indexing_error will raise[39;00m
[1;32m   3808[0m     [38;5;66;03m#  InvalidIndexError. Otherwise we fall through and re-raise[39;00m
[1;32m   3809[0m     [38;5;66;03m#  the TypeError.[39;00m
[1;32m   3810[0m     [38;5;28mself[39m[38;5;241m.[39m_check_indexing_error(key)

[0;31mKeyError[0m: 'proposal_title'
KeyError: 'proposal_title'

